<sdf version='1.4'>
  <world name='default'>
    <light name='sun' type='directional'>
      <cast_shadows>1</cast_shadows>
      <pose>0 0 10 0 -0 0</pose>
      <diffuse>0.8 0.8 0.8 1</diffuse>
      <specular>0.2 0.2 0.2 1</specular>
      <attenuation>
        <range>1000</range>
        <constant>0.9</constant>
        <linear>0.01</linear>
        <quadratic>0.001</quadratic>
      </attenuation>
      <direction>-0.5 0.1 -0.9</direction>
    </light>
    <model name='ground_plane'>
      <static>1</static>
      <link name='link'>
        <collision name='collision'>
          <geometry>
            <plane>
              <normal>0 0 1</normal>
              <size>100 100</size>
            </plane>
          </geometry>
          <surface>
            <friction>
              <ode>
                <mu>100</mu>
                <mu2>50</mu2>
              </ode>
            </friction>
            <bounce/>
            <contact>
              <ode/>
            </contact>
          </surface>
          <max_contacts>10</max_contacts>
        </collision>
        <visual name='visual'>
          <cast_shadows>0</cast_shadows>
          <geometry>
            <plane>
              <normal>0 0 1</normal>
              <size>100 100</size>
            </plane>
          </geometry>
          <material>
            <script>
              <uri>file://media/materials/scripts/gazebo.material</uri>
              <name>Gazebo/Grey</name>
            </script>
          </material>
        </visual>
        <velocity_decay>
          <linear>0</linear>
          <angular>0</angular>
        </velocity_decay>
        <self_collide>0</self_collide>
        <kinematic>0</kinematic>
        <gravity>1</gravity>
      </link>
    </model>
    <physics type='ode'>
      <max_step_size>0.001</max_step_size>
      <real_time_factor>1</real_time_factor>
      <real_time_update_rate>1000</real_time_update_rate>
      <gravity>0 0 -9.8</gravity>
    </physics>
    <scene>
      <ambient>0.4 0.4 0.4 1</ambient>
      <background>0.7 0.7 0.7 1</background>
      <shadows>1</shadows>
    </scene>
    <spherical_coordinates>
      <surface_model>EARTH_WGS84</surface_model>
      <latitude_deg>0</latitude_deg>
      <longitude_deg>0</longitude_deg>
      <elevation>0</elevation>
      <heading_deg>0</heading_deg>
    </spherical_coordinates>
    <model name='darwin'>
      <link name='base_link'>
        <pose>0 0 0 0 -0 0</pose>
        <inertial>
          <pose>-0.00302297 -0.0380721 -0.0190863 0 -0 0</pose>
          <mass>0.995599</mass>
          <inertia>
            <ixx>9.32461</ixx>
            <ixy>-0.254601</ixy>
            <ixz>2.03182</ixz>
            <iyy>17.0421</iyy>
            <iyz>-0.164173</iyz>
            <izz>18.0893</izz>
          </inertia>
        </inertial>
        <collision name='base_link_collision_MP_BACK_L'>
          <pose>0 0.06035 0 -1.5708 0 0</pose>
          <geometry>
            <box>
              <size>0.001 0.001 0.001</size>
            </box>
          </geometry>
          <surface>
            <contact>
              <ode/>
            </contact>
            <friction>
              <ode/>
            </friction>
            <bounce/>
          </surface>
          <max_contacts>10</max_contacts>
        </collision>
        <collision name='base_link_collision_MP_BACK_R'>
          <pose>0 -0.06035 0 1.5708 -0 0</pose>
          <geometry>
            <box>
              <size>0.001 0.001 0.001</size>
            </box>
          </geometry>
          <surface>
            <contact>
              <ode/>
            </contact>
            <friction>
              <ode/>
            </friction>
            <bounce/>
          </surface>
          <max_contacts>10</max_contacts>
        </collision>
        <collision name='base_link_collision_MP_BODY'>
          <pose>0 0 0 0 -0 0</pose>
          <geometry>
            <mesh>
              <scale>1 1 1</scale>
              <uri>/home/nao/ros_catkin_ecg_ws/src/darwin_description/meshes/body_coll.stl</uri>
            </mesh>
          </geometry>
          <surface>
            <contact>
              <ode/>
            </contact>
            <friction>
              <ode/>
            </friction>
            <bounce/>
          </surface>
          <max_contacts>10</max_contacts>
        </collision>
        <visual name='base_link_visual_MP_BACK_L'>
          <pose>0 0.06035 0 -1.5708 0 0</pose>
          <geometry>
            <box>
              <size>0.001 0.001 0.001</size>
            </box>
          </geometry>
          <material>
            <script>
              <name>Gazebo/Grey</name>
              <uri>__default__</uri>
            </script>
          </material>
          <material>
            <script>
              <name>Gazebo/Grey</name>
              <uri>__default__</uri>
            </script>
          </material>
        </visual>
        <visual name='base_link_visual_MP_BACK_R'>
          <pose>0 -0.06035 0 1.5708 -0 0</pose>
          <geometry>
            <box>
              <size>0.001 0.001 0.001</size>
            </box>
          </geometry>
          <material>
            <script>
              <name>Gazebo/Grey</name>
              <uri>__default__</uri>
            </script>
          </material>
          <material>
            <script>
              <name>Gazebo/Grey</name>
              <uri>__default__</uri>
            </script>
          </material>
        </visual>
        <visual name='base_link_visual_MP_BODY'>
          <pose>0 0 0 0 -0 0</pose>
          <geometry>
            <mesh>
              <scale>1 1 1</scale>
              <uri>/home/nao/ros_catkin_ecg_ws/src/darwin_description/meshes/body.STL</uri>
            </mesh>
          </geometry>
          <material>
            <script>
              <name>Gazebo/Grey</name>
              <uri>__default__</uri>
            </script>
          </material>
          <material>
            <script>
              <name>Gazebo/Grey</name>
              <uri>__default__</uri>
            </script>
          </material>
        </visual>
        <velocity_decay>
          <linear>0</linear>
          <angular>0</angular>
        </velocity_decay>
        <velocity_decay>
          <linear>0</linear>
          <angular>0</angular>
        </velocity_decay>
        <gravity>1</gravity>
        <velocity_decay>
          <linear>0</linear>
          <angular>0</angular>
        </velocity_decay>
        <self_collide>0</self_collide>
        <kinematic>0</kinematic>
      </link>
      <link name='MP_SHOULDER_L'>
        <pose>0 0.06035 0 2.35619 -1.57079 2.35619</pose>
        <inertial>
          <pose>-0.0135226 0.0102641 0.00139357 0 -0 0</pose>
          <mass>0.025913</mass>
          <inertia>
            <ixx>0.00977582</ixx>
            <ixy>0.00169118</ixy>
            <ixz>-0.000451743</ixz>
            <iyy>0.0105111</iyy>
            <iyz>0.00033407</iyz>
            <izz>0.0054768</izz>
          </inertia>
        </inertial>
        <collision name='MP_SHOULDER_L_collision'>
          <pose>0 0 0 0 -0 0</pose>
          <geometry>
            <mesh>
              <scale>1 1 1</scale>
              <uri>/home/nao/ros_catkin_ecg_ws/src/darwin_description/meshes/shoulder_l_coll.stl</uri>
            </mesh>
          </geometry>
          <surface>
            <contact>
              <ode/>
            </contact>
            <friction>
              <ode/>
            </friction>
            <bounce/>
          </surface>
          <max_contacts>10</max_contacts>
        </collision>
        <visual name='MP_SHOULDER_L_visual'>
          <pose>0 0 0 0 -0 0</pose>
          <geometry>
            <mesh>
              <scale>1 1 1</scale>
              <uri>/home/nao/ros_catkin_ecg_ws/src/darwin_description/meshes/shoulder_l.STL</uri>
            </mesh>
          </geometry>
          <material>
            <script>
              <name>Gazebo/Grey</name>
              <uri>__default__</uri>
            </script>
          </material>
          <material>
            <script>
              <name>Gazebo/Grey</name>
              <uri>__default__</uri>
            </script>
          </material>
        </visual>
        <gravity>1</gravity>
        <velocity_decay>
          <linear>0</linear>
          <angular>0</angular>
        </velocity_decay>
        <self_collide>0</self_collide>
        <kinematic>0</kinematic>
      </link>
      <joint name='j_shoulder_l' type='revolute'>
        <child>MP_SHOULDER_L</child>
        <parent>base_link</parent>
        <axis>
          <xyz>0 1 0</xyz>
          <limit>
            <lower>-2.61799</lower>
            <upper>2.61799</upper>
            <effort>2.8</effort>
            <velocity>5.65487</velocity>
          </limit>
          <dynamics/>
        </axis>
      </joint>
      <link name='MP_ARM_HIGH_L'>
        <pose>-4.28718e-10 0.082 -0.016 1.5708 -1.66533e-16 -1.5708</pose>
        <inertial>
          <pose>-0.036239 0.000734 0.00066 0 -0 0</pose>
          <mass>0.168377</mass>
          <inertia>
            <ixx>0.122028</ixx>
            <ixy>-0.00208126</ixy>
            <ixz>-0.000881434</ixz>
            <iyy>0.0380884</iyy>
            <iyz>0.00182514</iyz>
            <izz>0.113408</izz>
          </inertia>
        </inertial>
        <collision name='MP_ARM_HIGH_L_collision'>
          <pose>0 0 0 0 -0 0</pose>
          <geometry>
            <mesh>
              <scale>1 1 1</scale>
              <uri>/home/nao/ros_catkin_ecg_ws/src/darwin_description/meshes/arm_high_l_coll.stl</uri>
            </mesh>
          </geometry>
          <surface>
            <contact>
              <ode/>
            </contact>
            <friction>
              <ode/>
            </friction>
            <bounce/>
          </surface>
          <max_contacts>10</max_contacts>
        </collision>
        <visual name='MP_ARM_HIGH_L_visual'>
          <pose>0 0 0 0 -0 0</pose>
          <geometry>
            <mesh>
              <scale>1 1 1</scale>
              <uri>/home/nao/ros_catkin_ecg_ws/src/darwin_description/meshes/arm_high_l.STL</uri>
            </mesh>
          </geometry>
          <material>
            <script>
              <name>Gazebo/Grey</name>
              <uri>__default__</uri>
            </script>
          </material>
          <material>
            <script>
              <name>Gazebo/Grey</name>
              <uri>__default__</uri>
            </script>
          </material>
        </visual>
        <gravity>1</gravity>
        <velocity_decay>
          <linear>0</linear>
          <angular>0</angular>
        </velocity_decay>
        <self_collide>0</self_collide>
        <kinematic>0</kinematic>
      </link>
      <joint name='j_high_arm_l' type='revolute'>
        <child>MP_ARM_HIGH_L</child>
        <parent>MP_SHOULDER_L</parent>
        <axis>
          <xyz>-1 0 0</xyz>
          <limit>
            <lower>-2.61799</lower>
            <upper>2.61799</upper>
            <effort>2.8</effort>
            <velocity>5.64867</velocity>
          </limit>
          <dynamics/>
        </axis>
      </joint>
      <link name='MP_ARM_LOW_L'>
        <pose>0.016 0.142 -0.016 8.03847e-08 1.42407e-13 1.57079</pose>
        <inertial>
          <pose>0 0 0 0 -0 0</pose>
          <mass>0.0592885</mass>
          <inertia>
            <ixx>0.0868553</ixx>
            <ixy>0.00530203</ixy>
            <ixz>0.000436361</ixz>
            <iyy>0.0211921</iyy>
            <iyz>-0.00648559</iyz>
            <izz>0.0868455</izz>
          </inertia>
        </inertial>
        <collision name='MP_ARM_LOW_L_collision'>
          <pose>0.016 0.016 0 0 -0 0</pose>
          <geometry>
            <box>
              <size>0.032 0.032 0.035</size>
            </box>
          </geometry>
          <surface>
            <contact>
              <ode/>
            </contact>
            <friction>
              <ode/>
            </friction>
            <bounce/>
          </surface>
          <max_contacts>10</max_contacts>
        </collision>
        <visual name='MP_ARM_LOW_L_visual'>
          <pose>0.016 0.016 0 0 -0 0</pose>
          <geometry>
            <box>
              <size>0.032 0.032 0.035</size>
            </box>
          </geometry>
          <material>
            <script>
              <name>Gazebo/Grey</name>
              <uri>__default__</uri>
            </script>
          </material>
          <material>
            <script>
              <name>Gazebo/Grey</name>
              <uri>__default__</uri>
            </script>
          </material>
        </visual>
        <gravity>1</gravity>
        <velocity_decay>
          <linear>0</linear>
          <angular>0</angular>
        </velocity_decay>
        <self_collide>0</self_collide>
        <kinematic>0</kinematic>
      </link>
      <joint name='j_low_arm_l' type='revolute'>
        <child>MP_ARM_LOW_L</child>
        <parent>MP_ARM_HIGH_L</parent>
        <axis>
          <xyz>0 0 1</xyz>
          <limit>
            <lower>-2.61799</lower>
            <upper>2.61799</upper>
            <effort>2.8</effort>
            <velocity>5.65487</velocity>
          </limit>
          <dynamics/>
        </axis>
      </joint>
      <link name='MP_ARM_GRIPPER_FIX_L'>
        <pose>1.26944e-07 0.19 -0.016 1.5708 1.42497e-13 1.57079</pose>
        <inertial>
          <pose>0.054919 -0.011745 0.003333 0 -0 0</pose>
          <mass>0.02</mass>
          <inertia>
            <ixx>0.244057</ixx>
            <ixy>-0.00416284</ixy>
            <ixz>-0.00176226</ixz>
            <iyy>0.0761788</iyy>
            <iyz>0.00365041</iyz>
            <izz>0.226818</izz>
          </inertia>
        </inertial>
        <collision name='MP_ARM_GRIPPER_FIX_L_collision'>
          <pose>0.016 0 0 0 -0 0</pose>
          <geometry>
            <box>
              <size>0.064 0.032 0.032</size>
            </box>
          </geometry>
          <surface>
            <contact>
              <ode/>
            </contact>
            <friction>
              <ode/>
            </friction>
            <bounce/>
          </surface>
          <max_contacts>10</max_contacts>
        </collision>
        <collision name='MP_ARM_GRIPPER_FIX_L_collision_MP_ARM_GRIPPER_FIX_DUMMY_L'>
          <pose>0.064 -0.01 0 0 -0 0</pose>
          <geometry>
            <box>
              <size>0.032 0.005 0.032</size>
            </box>
          </geometry>
          <surface>
            <contact>
              <ode/>
            </contact>
            <friction>
              <ode/>
            </friction>
            <bounce/>
          </surface>
          <surface>
            <contact>
              <ode/>
            </contact>
            <friction>
              <ode/>
            </friction>
          </surface>
          <max_contacts>10</max_contacts>
        </collision>
        <visual name='MP_ARM_GRIPPER_FIX_L_visual'>
          <pose>0.016 0 0 0 -0 0</pose>
          <geometry>
            <box>
              <size>0.064 0.032 0.032</size>
            </box>
          </geometry>
          <material>
            <script>
              <name>Gazebo/Grey</name>
              <uri>__default__</uri>
            </script>
          </material>
          <material>
            <script>
              <name>Gazebo/Grey</name>
              <uri>__default__</uri>
            </script>
          </material>
        </visual>
        <visual name='MP_ARM_GRIPPER_FIX_L_visual_MP_ARM_GRIPPER_FIX_DUMMY_L'>
          <pose>0.064 -0.01 0 0 -0 0</pose>
          <geometry>
            <box>
              <size>0.032 0.005 0.032</size>
            </box>
          </geometry>
          <material>
            <script>
              <name>Gazebo/Grey</name>
              <uri>__default__</uri>
            </script>
          </material>
          <material>
            <script>
              <name>Gazebo/Grey</name>
              <uri>__default__</uri>
            </script>
          </material>
        </visual>
        <velocity_decay>
          <linear>0</linear>
          <angular>0</angular>
        </velocity_decay>
        <gravity>1</gravity>
        <velocity_decay>
          <linear>0</linear>
          <angular>0</angular>
        </velocity_decay>
        <self_collide>0</self_collide>
        <kinematic>0</kinematic>
      </link>
      <joint name='j_wrist_l' type='revolute'>
        <child>MP_ARM_GRIPPER_FIX_L</child>
        <parent>MP_ARM_LOW_L</parent>
        <axis>
          <xyz>1 -3e-06 0</xyz>
          <limit>
            <lower>-2.61799</lower>
            <upper>2.61799</upper>
            <effort>2.8</effort>
            <velocity>5.65487</velocity>
          </limit>
          <dynamics/>
        </axis>
      </joint>
      <link name='MP_ARM_GRIPPER_MOV_L'>
        <pose>2.54852e-07 0.238 -0.006 1.5708 -1 1.57079</pose>
        <inertial>
          <pose>0 0 0 0 -0 0</pose>
          <mass>0.01</mass>
          <inertia>
            <ixx>0.122028</ixx>
            <ixy>-0.00208126</ixy>
            <ixz>-0.000881434</ixz>
            <iyy>0.0380884</iyy>
            <iyz>0.00182514</iyz>
            <izz>0.113408</izz>
          </inertia>
        </inertial>
        <collision name='MP_ARM_GRIPPER_MOV_L_collision'>
          <pose>0.016 0 0 0 -0 0</pose>
          <geometry>
            <box>
              <size>0.032 0.005 0.032</size>
            </box>
          </geometry>
          <surface>
            <contact>
              <ode/>
            </contact>
            <friction>
              <ode/>
            </friction>
            <bounce/>
          </surface>
          <max_contacts>10</max_contacts>
        </collision>
        <collision name='MP_ARM_GRIPPER_MOV_L_collision_MP_ARM_GRIPPER_MOV_L_1'>
          <pose>0.031 -0.0025 0 0 -0 0</pose>
          <geometry>
            <box>
              <size>0.002 0.01 0.032</size>
            </box>
          </geometry>
          <surface>
            <contact>
              <ode/>
            </contact>
            <friction>
              <ode/>
            </friction>
            <bounce/>
          </surface>
          <max_contacts>10</max_contacts>
        </collision>
        <visual name='MP_ARM_GRIPPER_MOV_L_visual'>
          <pose>0.016 0 0 0 -0 0</pose>
          <geometry>
            <box>
              <size>0.032 0.005 0.032</size>
            </box>
          </geometry>
          <material>
            <script>
              <name>Gazebo/Grey</name>
              <uri>__default__</uri>
            </script>
          </material>
          <material>
            <script>
              <name>Gazebo/Grey</name>
              <uri>__default__</uri>
            </script>
          </material>
        </visual>
        <visual name='MP_ARM_GRIPPER_MOV_L_visual_MP_ARM_GRIPPER_MOV_L_1'>
          <pose>0.031 -0.0025 0 0 -0 0</pose>
          <geometry>
            <box>
              <size>0.002 0.01 0.032</size>
            </box>
          </geometry>
          <material>
            <script>
              <name>Gazebo/Grey</name>
              <uri>__default__</uri>
            </script>
          </material>
          <material>
            <script>
              <name>Gazebo/Grey</name>
              <uri>__default__</uri>
            </script>
          </material>
        </visual>
        <gravity>1</gravity>
        <velocity_decay>
          <linear>0</linear>
          <angular>0</angular>
        </velocity_decay>
        <self_collide>0</self_collide>
        <kinematic>0</kinematic>
      </link>
      <joint name='j_gripper_l' type='revolute'>
        <child>MP_ARM_GRIPPER_MOV_L</child>
        <parent>MP_ARM_GRIPPER_FIX_L</parent>
        <axis>
          <xyz>1 -3e-06 0</xyz>
          <limit>
            <lower>-2.61799</lower>
            <upper>2.61799</upper>
            <effort>2.8</effort>
            <velocity>5.65487</velocity>
          </limit>
          <dynamics/>
        </axis>
      </joint>
      <link name='MP_SHOULDER_R'>
        <pose>0 -0.06035 0 -2.35619 1.57079 2.35619</pose>
        <inertial>
          <pose>-0.013523 0.010264 0.001394 0 -0 0</pose>
          <mass>0.025913</mass>
          <inertia>
            <ixx>0.00977582</ixx>
            <ixy>0.00169118</ixy>
            <ixz>-0.000451743</ixz>
            <iyy>0.0105111</iyy>
            <iyz>0.00033407</iyz>
            <izz>0.0054768</izz>
          </inertia>
        </inertial>
        <collision name='MP_SHOULDER_R_collision'>
          <pose>0 0 0 0 -0 3.14</pose>
          <geometry>
            <mesh>
              <scale>1 1 1</scale>
              <uri>/home/nao/ros_catkin_ecg_ws/src/darwin_description/meshes/shoulder_r_coll.stl</uri>
            </mesh>
          </geometry>
          <surface>
            <contact>
              <ode/>
            </contact>
            <friction>
              <ode/>
            </friction>
            <bounce/>
          </surface>
          <max_contacts>10</max_contacts>
        </collision>
        <visual name='MP_SHOULDER_R_visual'>
          <pose>0 0 0 0 -0 3.14</pose>
          <geometry>
            <mesh>
              <scale>1 1 1</scale>
              <uri>/home/nao/ros_catkin_ecg_ws/src/darwin_description/meshes/shoulder_r.STL</uri>
            </mesh>
          </geometry>
          <material>
            <script>
              <name>Gazebo/Grey</name>
              <uri>__default__</uri>
            </script>
          </material>
          <material>
            <script>
              <name>Gazebo/Grey</name>
              <uri>__default__</uri>
            </script>
          </material>
        </visual>
        <gravity>1</gravity>
        <velocity_decay>
          <linear>0</linear>
          <angular>0</angular>
        </velocity_decay>
        <self_collide>0</self_collide>
        <kinematic>0</kinematic>
      </link>
      <joint name='j_shoulder_r' type='revolute'>
        <child>MP_SHOULDER_R</child>
        <parent>base_link</parent>
        <axis>
          <xyz>0 -1 0</xyz>
          <limit>
            <lower>-2.61799</lower>
            <upper>2.61799</upper>
            <effort>2.8</effort>
            <velocity>5.65487</velocity>
          </limit>
          <dynamics/>
        </axis>
      </joint>
      <link name='MP_ARM_HIGH_R'>
        <pose>4.28718e-10 -0.082 -0.016 1.5708 5.35898e-08 1.5708</pose>
        <inertial>
          <pose>-0.036239 0.000734 -0.00066 0 -0 0</pose>
          <mass>0.168377</mass>
          <inertia>
            <ixx>0.122028</ixx>
            <ixy>-0.00208126</ixy>
            <ixz>-0.000881434</ixz>
            <iyy>0.0380884</iyy>
            <iyz>0.00182514</iyz>
            <izz>0.113408</izz>
          </inertia>
        </inertial>
        <collision name='MP_ARM_HIGH_R_collision'>
          <pose>0 0 0 0 -0 0</pose>
          <geometry>
            <mesh>
              <scale>1 1 1</scale>
              <uri>/home/nao/ros_catkin_ecg_ws/src/darwin_description/meshes/arm_high_r_coll.stl</uri>
            </mesh>
          </geometry>
          <surface>
            <contact>
              <ode/>
            </contact>
            <friction>
              <ode/>
            </friction>
            <bounce/>
          </surface>
          <max_contacts>10</max_contacts>
        </collision>
        <visual name='MP_ARM_HIGH_R_visual'>
          <pose>0 0 0 3.14 -0 0</pose>
          <geometry>
            <mesh>
              <scale>1 1 1</scale>
              <uri>/home/nao/ros_catkin_ecg_ws/src/darwin_description/meshes/arm_high_r.STL</uri>
            </mesh>
          </geometry>
          <material>
            <script>
              <name>Gazebo/Grey</name>
              <uri>__default__</uri>
            </script>
          </material>
          <material>
            <script>
              <name>Gazebo/Grey</name>
              <uri>__default__</uri>
            </script>
          </material>
        </visual>
        <gravity>1</gravity>
        <velocity_decay>
          <linear>0</linear>
          <angular>0</angular>
        </velocity_decay>
        <self_collide>0</self_collide>
        <kinematic>0</kinematic>
      </link>
      <joint name='j_high_arm_r' type='revolute'>
        <child>MP_ARM_HIGH_R</child>
        <parent>MP_SHOULDER_R</parent>
        <axis>
          <xyz>1 0 0</xyz>
          <limit>
            <lower>-2.61799</lower>
            <upper>2.61799</upper>
            <effort>2.8</effort>
            <velocity>5.64867</velocity>
          </limit>
          <dynamics/>
        </axis>
      </joint>
      <link name='MP_ARM_LOW_R'>
        <pose>0.016 -0.142 -0.016 2.6795e-08 -5.35898e-08 -1.5708</pose>
        <inertial>
          <pose>0 0 0 0 -0 0</pose>
          <mass>0.0592885</mass>
          <inertia>
            <ixx>0.0868553</ixx>
            <ixy>0.00530203</ixy>
            <ixz>0.000436361</ixz>
            <iyy>0.0211921</iyy>
            <iyz>-0.00648559</iyz>
            <izz>0.0868455</izz>
          </inertia>
        </inertial>
        <collision name='MP_ARM_LOW_R_collision'>
          <pose>0.016 -0.016 0 0 -0 0</pose>
          <geometry>
            <box>
              <size>0.032 0.032 0.035</size>
            </box>
          </geometry>
          <surface>
            <contact>
              <ode/>
            </contact>
            <friction>
              <ode/>
            </friction>
            <bounce/>
          </surface>
          <max_contacts>10</max_contacts>
        </collision>
        <visual name='MP_ARM_LOW_R_visual'>
          <pose>0.016 -0.016 0 0 -0 0</pose>
          <geometry>
            <box>
              <size>0.032 0.032 0.035</size>
            </box>
          </geometry>
          <material>
            <script>
              <name>Gazebo/Grey</name>
              <uri>__default__</uri>
            </script>
          </material>
          <material>
            <script>
              <name>Gazebo/Grey</name>
              <uri>__default__</uri>
            </script>
          </material>
        </visual>
        <gravity>1</gravity>
        <velocity_decay>
          <linear>0</linear>
          <angular>0</angular>
        </velocity_decay>
        <self_collide>0</self_collide>
        <kinematic>0</kinematic>
      </link>
      <joint name='j_low_arm_r' type='revolute'>
        <child>MP_ARM_LOW_R</child>
        <parent>MP_ARM_HIGH_R</parent>
        <axis>
          <xyz>0 0 1</xyz>
          <limit>
            <lower>-1.635</lower>
            <upper>2.61799</upper>
            <effort>2.8</effort>
            <velocity>5.65487</velocity>
          </limit>
          <dynamics/>
        </axis>
      </joint>
      <link name='MP_ARM_GRIPPER_FIX_R'>
        <pose>-1.26944e-07 -0.19 -0.016 1.5708 -5.35898e-08 -1.5708</pose>
        <inertial>
          <pose>0.054919 -0.011745 0.003333 0 -0 0</pose>
          <mass>0.02</mass>
          <inertia>
            <ixx>0.244057</ixx>
            <ixy>-0.00416284</ixy>
            <ixz>-0.00176226</ixz>
            <iyy>0.0761788</iyy>
            <iyz>0.00365041</iyz>
            <izz>0.226818</izz>
          </inertia>
        </inertial>
        <collision name='MP_ARM_GRIPPER_FIX_R_collision'>
          <pose>0.016 0 0 0 -0 0</pose>
          <geometry>
            <box>
              <size>0.064 0.032 0.032</size>
            </box>
          </geometry>
          <surface>
            <contact>
              <ode/>
            </contact>
            <friction>
              <ode/>
            </friction>
            <bounce/>
          </surface>
          <max_contacts>10</max_contacts>
        </collision>
        <collision name='MP_ARM_GRIPPER_FIX_R_collision_MP_ARM_GRIPPER_FIX_DUMMY_R'>
          <pose>0.064 -0.01 0 0 -0 0</pose>
          <geometry>
            <box>
              <size>0.032 0.005 0.032</size>
            </box>
          </geometry>
          <surface>
            <contact>
              <ode/>
            </contact>
            <friction>
              <ode/>
            </friction>
            <bounce/>
          </surface>
          <surface>
            <contact>
              <ode/>
            </contact>
            <friction>
              <ode/>
            </friction>
          </surface>
          <max_contacts>10</max_contacts>
        </collision>
        <visual name='MP_ARM_GRIPPER_FIX_R_visual'>
          <pose>0.016 0 0 0 -0 0</pose>
          <geometry>
            <box>
              <size>0.064 0.032 0.032</size>
            </box>
          </geometry>
          <material>
            <script>
              <name>Gazebo/Grey</name>
              <uri>__default__</uri>
            </script>
          </material>
          <material>
            <script>
              <name>Gazebo/Grey</name>
              <uri>__default__</uri>
            </script>
          </material>
        </visual>
        <visual name='MP_ARM_GRIPPER_FIX_R_visual_MP_ARM_GRIPPER_FIX_DUMMY_R'>
          <pose>0.064 -0.01 0 0 -0 0</pose>
          <geometry>
            <box>
              <size>0.032 0.005 0.032</size>
            </box>
          </geometry>
          <material>
            <script>
              <name>Gazebo/Grey</name>
              <uri>__default__</uri>
            </script>
          </material>
          <material>
            <script>
              <name>Gazebo/Grey</name>
              <uri>__default__</uri>
            </script>
          </material>
        </visual>
        <velocity_decay>
          <linear>0</linear>
          <angular>0</angular>
        </velocity_decay>
        <gravity>1</gravity>
        <velocity_decay>
          <linear>0</linear>
          <angular>0</angular>
        </velocity_decay>
        <self_collide>0</self_collide>
        <kinematic>0</kinematic>
      </link>
      <joint name='j_wrist_r' type='revolute'>
        <child>MP_ARM_GRIPPER_FIX_R</child>
        <parent>MP_ARM_LOW_R</parent>
        <axis>
          <xyz>-1 3e-06 0</xyz>
          <limit>
            <lower>-2.61799</lower>
            <upper>2.61799</upper>
            <effort>2.8</effort>
            <velocity>5.65487</velocity>
          </limit>
          <dynamics/>
        </axis>
      </joint>
      <link name='MP_ARM_GRIPPER_MOV_R'>
        <pose>-2.54316e-07 -0.238 -0.00599999 1.5708 -1 -1.5708</pose>
        <inertial>
          <pose>0 0 0 0 -0 0</pose>
          <mass>0.01</mass>
          <inertia>
            <ixx>0.122028</ixx>
            <ixy>-0.00208126</ixy>
            <ixz>-0.000881434</ixz>
            <iyy>0.0380884</iyy>
            <iyz>0.00182514</iyz>
            <izz>0.113408</izz>
          </inertia>
        </inertial>
        <collision name='MP_ARM_GRIPPER_MOV_R_collision'>
          <pose>0.016 0 0 0 -0 0</pose>
          <geometry>
            <box>
              <size>0.032 0.005 0.032</size>
            </box>
          </geometry>
          <surface>
            <contact>
              <ode/>
            </contact>
            <friction>
              <ode/>
            </friction>
            <bounce/>
          </surface>
          <max_contacts>10</max_contacts>
        </collision>
        <collision name='MP_ARM_GRIPPER_MOV_R_collision_MP_ARM_GRIPPER_MOV_R_1'>
          <pose>0.031 -0.0025 0 0 -0 0</pose>
          <geometry>
            <box>
              <size>0.002 0.01 0.032</size>
            </box>
          </geometry>
          <surface>
            <contact>
              <ode/>
            </contact>
            <friction>
              <ode/>
            </friction>
            <bounce/>
          </surface>
          <max_contacts>10</max_contacts>
        </collision>
        <visual name='MP_ARM_GRIPPER_MOV_R_visual'>
          <pose>0.016 0 0 0 -0 0</pose>
          <geometry>
            <box>
              <size>0.032 0.005 0.032</size>
            </box>
          </geometry>
          <material>
            <script>
              <name>Gazebo/Grey</name>
              <uri>__default__</uri>
            </script>
          </material>
          <material>
            <script>
              <name>Gazebo/Grey</name>
              <uri>__default__</uri>
            </script>
          </material>
        </visual>
        <visual name='MP_ARM_GRIPPER_MOV_R_visual_MP_ARM_GRIPPER_MOV_R_1'>
          <pose>0.031 -0.0025 0 0 -0 0</pose>
          <geometry>
            <box>
              <size>0.002 0.01 0.032</size>
            </box>
          </geometry>
          <material>
            <script>
              <name>Gazebo/Grey</name>
              <uri>__default__</uri>
            </script>
          </material>
          <material>
            <script>
              <name>Gazebo/Grey</name>
              <uri>__default__</uri>
            </script>
          </material>
        </visual>
        <gravity>1</gravity>
        <velocity_decay>
          <linear>0</linear>
          <angular>0</angular>
        </velocity_decay>
        <self_collide>0</self_collide>
        <kinematic>0</kinematic>
      </link>
      <joint name='j_gripper_r' type='revolute'>
        <child>MP_ARM_GRIPPER_MOV_R</child>
        <parent>MP_ARM_GRIPPER_FIX_R</parent>
        <axis>
          <xyz>-1 3e-06 0</xyz>
          <limit>
            <lower>-2.61799</lower>
            <upper>2.61799</upper>
            <effort>2.8</effort>
            <velocity>5.65487</velocity>
          </limit>
          <dynamics/>
        </axis>
      </joint>
      <link name='MP_NECK'>
        <pose>0 0 0.0235 0 -0 1.5708</pose>
        <inertial>
          <pose>0.001424 -0.016567 -0.007128 0 -0 0</pose>
          <mass>0.0243577</mass>
          <inertia>
            <ixx>0.00514111</ixx>
            <ixy>-0.000575303</ixy>
            <ixz>-2.4729e-05</ixz>
            <iyy>0.00819157</iyy>
            <iyz>-1.92231e-05</iyz>
            <izz>0.00113798</izz>
          </inertia>
        </inertial>
        <collision name='MP_NECK_collision'>
          <pose>0 0 0 0 -0 0</pose>
          <geometry>
            <mesh>
              <scale>1 1 1</scale>
              <uri>/home/nao/ros_catkin_ecg_ws/src/darwin_description/meshes/neck_coll.stl</uri>
            </mesh>
          </geometry>
          <surface>
            <contact>
              <ode/>
            </contact>
            <friction>
              <ode/>
            </friction>
            <bounce/>
          </surface>
          <max_contacts>10</max_contacts>
        </collision>
        <visual name='MP_NECK_visual'>
          <pose>0 0 0 0 -0 0</pose>
          <geometry>
            <mesh>
              <scale>1 1 1</scale>
              <uri>/home/nao/ros_catkin_ecg_ws/src/darwin_description/meshes/neck.STL</uri>
            </mesh>
          </geometry>
          <material>
            <script>
              <name>Gazebo/Grey</name>
              <uri>__default__</uri>
            </script>
          </material>
          <material>
            <script>
              <name>Gazebo/Grey</name>
              <uri>__default__</uri>
            </script>
          </material>
        </visual>
        <gravity>1</gravity>
        <velocity_decay>
          <linear>0</linear>
          <angular>0</angular>
        </velocity_decay>
        <self_collide>0</self_collide>
        <kinematic>0</kinematic>
      </link>
      <joint name='j_pan' type='revolute'>
        <child>MP_NECK</child>
        <parent>base_link</parent>
        <axis>
          <xyz>0 0 1</xyz>
          <limit>
            <lower>-2.61799</lower>
            <upper>2.61799</upper>
            <effort>2.8</effort>
            <velocity>5.65487</velocity>
          </limit>
          <dynamics/>
        </axis>
      </joint>
      <link name='MP_HEAD'>
        <pose>0 0 0.05065 -1.5708 1.14248e-17 3.14159</pose>
        <inertial>
          <pose>6.4e-05 -0.018565 -0.007667 0 -0 0</pose>
          <mass>0.158042</mass>
          <inertia>
            <ixx>0.123968</ixx>
            <ixy>7.84944e-05</ixy>
            <ixz>7.64598e-06</ixz>
            <iyy>0.117838</iyy>
            <iyz>0.00121992</iyz>
            <izz>0.15836</izz>
          </inertia>
        </inertial>
        <collision name='MP_HEAD_collision'>
          <pose>0 0 0 0 -0 0</pose>
          <geometry>
            <mesh>
              <scale>1 1 1</scale>
              <uri>/home/nao/ros_catkin_ecg_ws/src/darwin_description/meshes/head_coll.stl</uri>
            </mesh>
          </geometry>
          <surface>
            <contact>
              <ode/>
            </contact>
            <friction>
              <ode/>
            </friction>
            <bounce/>
          </surface>
          <surface>
            <contact>
              <ode/>
            </contact>
            <friction>
              <ode/>
            </friction>
          </surface>
          <max_contacts>10</max_contacts>
        </collision>
        <visual name='MP_HEAD_visual'>
          <pose>0 0 0 0 -0 0</pose>
          <geometry>
            <mesh>
              <scale>1 1 1</scale>
              <uri>/home/nao/ros_catkin_ecg_ws/src/darwin_description/meshes/head.STL</uri>
            </mesh>
          </geometry>
          <material>
            <script>
              <name>Gazebo/Grey</name>
              <uri>__default__</uri>
            </script>
          </material>
          <material>
            <script>
              <name>Gazebo/Grey</name>
              <uri>__default__</uri>
            </script>
          </material>
        </visual>
        <velocity_decay>
          <linear>0</linear>
          <angular>0</angular>
        </velocity_decay>
        <velocity_decay>
          <linear>0</linear>
          <angular>0</angular>
        </velocity_decay>
        <sensor name='camera' type='camera'>
          <pose>-0.05 -0.01 0 -1.5708 -0 -3.14159</pose>
          <camera name='__default__'>
            <horizontal_fov>1.0123</horizontal_fov>
            <image>
              <width>320</width>
              <height>200</height>
            </image>
            <clip>
              <near>0.001</near>
              <far>100</far>
            </clip>
          </camera>
          <always_on>1</always_on>
          <update_rate>30</update_rate>
          <visualize>1</visualize>
          <plugin name='camera_controller' filename='libgazebo_ros_camera.so'>
            <alwaysOn>true</alwaysOn>
            <updateRate>30</updateRate>
            <cameraName>darwin/camera</cameraName>
            <imageTopicName>image_raw</imageTopicName>
            <cameraInfoTopicName>camera_info</cameraInfoTopicName>
            <frameName>camera_link</frameName>
            <hackBaseline>0.07</hackBaseline>
            <distortionK1>0.0</distortionK1>
            <distortionK2>0.0</distortionK2>
            <distortionK3>0.0</distortionK3>
            <distortionT1>0.0</distortionT1>
            <distortionT2>0.0</distortionT2>
            <robotNamespace>/</robotNamespace>
          </plugin>
        </sensor>
        <gravity>1</gravity>
        <velocity_decay>
          <linear>0</linear>
          <angular>0</angular>
        </velocity_decay>
        <self_collide>0</self_collide>
        <kinematic>0</kinematic>
      </link>
      <joint name='j_tilt' type='revolute'>
        <child>MP_HEAD</child>
        <parent>MP_NECK</parent>
        <axis>
          <xyz>0 -1 0</xyz>
          <limit>
            <lower>-2.61799</lower>
            <upper>2.61799</upper>
            <effort>2.8</effort>
            <velocity>5.65487</velocity>
          </limit>
          <dynamics/>
        </axis>
      </joint>
      <link name='MP_PELVIS_L'>
        <pose>-0.005 0.037 -0.09355 3.14159 2.65359e-06 1.5708</pose>
        <inertial>
          <pose>0 0.00048 0.018437 0 -0 0</pose>
          <mass>0.167</mass>
          <inertia>
            <ixx>0.122597</ixx>
            <ixy>0.000711275</ixy>
            <ixz>0.000811439</ixz>
            <iyy>0.110666</iyy>
            <iyz>-0.00716355</iyz>
            <izz>0.0418777</izz>
          </inertia>
        </inertial>
        <collision name='MP_PELVIS_L_collision'>
          <pose>0 0 0 0 -0 0</pose>
          <geometry>
            <mesh>
              <scale>1 1 1</scale>
              <uri>/home/nao/ros_catkin_ecg_ws/src/darwin_description/meshes/pelvis_l_coll.stl</uri>
            </mesh>
          </geometry>
          <surface>
            <contact>
              <ode/>
            </contact>
            <friction>
              <ode/>
            </friction>
            <bounce/>
          </surface>
          <max_contacts>10</max_contacts>
        </collision>
        <visual name='MP_PELVIS_L_visual'>
          <pose>0 0 0 0 -0 0</pose>
          <geometry>
            <mesh>
              <scale>1 1 1</scale>
              <uri>/home/nao/ros_catkin_ecg_ws/src/darwin_description/meshes/pelvis_l.STL</uri>
            </mesh>
          </geometry>
          <material>
            <script>
              <name>Gazebo/Grey</name>
              <uri>__default__</uri>
            </script>
          </material>
          <material>
            <script>
              <name>Gazebo/Grey</name>
              <uri>__default__</uri>
            </script>
          </material>
        </visual>
        <gravity>1</gravity>
        <velocity_decay>
          <linear>0</linear>
          <angular>0</angular>
        </velocity_decay>
        <self_collide>0</self_collide>
        <kinematic>0</kinematic>
      </link>
      <joint name='j_pelvis_l' type='revolute'>
        <child>MP_PELVIS_L</child>
        <parent>base_link</parent>
        <axis>
          <xyz>0 -3e-06 -1</xyz>
          <limit>
            <lower>-2.61799</lower>
            <upper>2.61799</upper>
            <effort>10</effort>
            <velocity>5.65487</velocity>
          </limit>
          <dynamics/>
        </axis>
      </joint>
      <link name='MP_THIGH1_L'>
        <pose>-0.005 0.0369999 -0.122202 -1.5708 2.65359e-06 1.5708</pose>
        <inertial>
          <pose>7.9e-05 0.018242 0.013873 0 -0 0</pose>
          <mass>0.119043</mass>
          <inertia>
            <ixx>0.0979503</ixx>
            <ixy>0.00121194</ixy>
            <ixz>-0.00021223</ixz>
            <iyy>0.0328483</iyy>
            <iyz>-0.0019474</iyz>
            <izz>0.114935</izz>
          </inertia>
        </inertial>
        <collision name='MP_THIGH1_L_collision'>
          <pose>0 0 0 0 -0 0</pose>
          <geometry>
            <mesh>
              <scale>1 1 1</scale>
              <uri>/home/nao/ros_catkin_ecg_ws/src/darwin_description/meshes/thigh1_l_coll.stl</uri>
            </mesh>
          </geometry>
          <surface>
            <contact>
              <ode/>
            </contact>
            <friction>
              <ode/>
            </friction>
            <bounce/>
          </surface>
          <max_contacts>10</max_contacts>
        </collision>
        <visual name='MP_THIGH1_L_visual'>
          <pose>0 0 0 0 -0 0</pose>
          <geometry>
            <mesh>
              <scale>1 1 1</scale>
              <uri>/home/nao/ros_catkin_ecg_ws/src/darwin_description/meshes/thigh1_l.STL</uri>
            </mesh>
          </geometry>
          <material>
            <script>
              <name>Gazebo/Grey</name>
              <uri>__default__</uri>
            </script>
          </material>
          <material>
            <script>
              <name>Gazebo/Grey</name>
              <uri>__default__</uri>
            </script>
          </material>
        </visual>
        <gravity>1</gravity>
        <velocity_decay>
          <linear>0</linear>
          <angular>0</angular>
        </velocity_decay>
        <self_collide>0</self_collide>
        <kinematic>0</kinematic>
      </link>
      <joint name='j_thigh1_l' type='revolute'>
        <child>MP_THIGH1_L</child>
        <parent>MP_PELVIS_L</parent>
        <axis>
          <xyz>-1 0 0</xyz>
          <limit>
            <lower>-2.61799</lower>
            <upper>2.61799</upper>
            <effort>10</effort>
            <velocity>5.65487</velocity>
          </limit>
          <dynamics/>
        </axis>
      </joint>
      <link name='MP_THIGH2_L'>
        <pose>-0.005 0.0369999 -0.122202 -0.00999635 -1.57079 1.58079</pose>
        <inertial>
          <pose>-0.062965 -0.000323 0.000692 0 -0 0</pose>
          <mass>0.119043</mass>
          <inertia>
            <ixx>0.0979503</ixx>
            <ixy>0.00121194</ixy>
            <ixz>-0.00021223</ixz>
            <iyy>0.0328483</iyy>
            <iyz>-0.0019474</iyz>
            <izz>0.114935</izz>
          </inertia>
        </inertial>
        <collision name='MP_THIGH2_L_collision'>
          <pose>0 0 0 0 -0 0</pose>
          <geometry>
            <mesh>
              <scale>1 1 1</scale>
              <uri>/home/nao/ros_catkin_ecg_ws/src/darwin_description/meshes/thigh2_l_coll.stl</uri>
            </mesh>
          </geometry>
          <surface>
            <contact>
              <ode/>
            </contact>
            <friction>
              <ode/>
            </friction>
            <bounce/>
          </surface>
          <max_contacts>10</max_contacts>
        </collision>
        <visual name='MP_THIGH2_L_visual'>
          <pose>0 0 0 0 -0 0</pose>
          <geometry>
            <mesh>
              <scale>1 1 1</scale>
              <uri>/home/nao/ros_catkin_ecg_ws/src/darwin_description/meshes/thigh2_l.STL</uri>
            </mesh>
          </geometry>
          <material>
            <script>
              <name>Gazebo/Grey</name>
              <uri>__default__</uri>
            </script>
          </material>
          <material>
            <script>
              <name>Gazebo/Grey</name>
              <uri>__default__</uri>
            </script>
          </material>
        </visual>
        <gravity>1</gravity>
        <velocity_decay>
          <linear>0</linear>
          <angular>0</angular>
        </velocity_decay>
        <self_collide>0</self_collide>
        <kinematic>0</kinematic>
      </link>
      <joint name='j_thigh2_l' type='revolute'>
        <child>MP_THIGH2_L</child>
        <parent>MP_THIGH1_L</parent>
        <axis>
          <xyz>0 -1 3e-06</xyz>
          <limit>
            <lower>-2.61799</lower>
            <upper>2.61799</upper>
            <effort>10</effort>
            <velocity>5.65487</velocity>
          </limit>
          <dynamics/>
        </axis>
      </joint>
      <link name='MP_TIBIA_L'>
        <pose>-0.005 0.0369997 -0.215202 -0.00999635 -1.57079 1.58079</pose>
        <inertial>
          <pose>-0.053955 0.006548 -0.000592 0 -0 0</pose>
          <mass>0.0703098</mass>
          <inertia>
            <ixx>0.0933696</ixx>
            <ixy>-0.000935674</ixy>
            <ixz>-0.000239921</ixz>
            <iyy>0.0462955</iyy>
            <iyz>-0.0128585</iyz>
            <izz>0.113515</izz>
          </inertia>
        </inertial>
        <collision name='MP_TIBIA_L_collision'>
          <pose>0 0 0 0 -0 0</pose>
          <geometry>
            <mesh>
              <scale>1 1 1</scale>
              <uri>/home/nao/ros_catkin_ecg_ws/src/darwin_description/meshes/tibia_l_coll.stl</uri>
            </mesh>
          </geometry>
          <surface>
            <contact>
              <ode/>
            </contact>
            <friction>
              <ode/>
            </friction>
            <bounce/>
          </surface>
          <max_contacts>10</max_contacts>
        </collision>
        <visual name='MP_TIBIA_L_visual'>
          <pose>0 0 0 0 -0 0</pose>
          <geometry>
            <mesh>
              <scale>1 1 1</scale>
              <uri>/home/nao/ros_catkin_ecg_ws/src/darwin_description/meshes/tibia_l.STL</uri>
            </mesh>
          </geometry>
          <material>
            <script>
              <name>Gazebo/Grey</name>
              <uri>__default__</uri>
            </script>
          </material>
          <material>
            <script>
              <name>Gazebo/Grey</name>
              <uri>__default__</uri>
            </script>
          </material>
        </visual>
        <gravity>1</gravity>
        <velocity_decay>
          <linear>0</linear>
          <angular>0</angular>
        </velocity_decay>
        <self_collide>0</self_collide>
        <kinematic>0</kinematic>
      </link>
      <joint name='j_tibia_l' type='revolute'>
        <child>MP_TIBIA_L</child>
        <parent>MP_THIGH2_L</parent>
        <axis>
          <xyz>0 -1 3e-06</xyz>
          <limit>
            <lower>-2.61799</lower>
            <upper>2.61799</upper>
            <effort>10</effort>
            <velocity>5.65487</velocity>
          </limit>
          <dynamics/>
        </axis>
      </joint>
      <link name='MP_ANKLE1_L'>
        <pose>-0.005 0.0369994 -0.308202 3.13159 -1.57079 1.58079</pose>
        <inertial>
          <pose>-0.000214 -0.018536 0.013873 0 -0 0</pose>
          <mass>0.167108</mass>
          <inertia>
            <ixx>0.120792</ixx>
            <ixy>-0.000797811</ixy>
            <ixz>-0.000393222</ixz>
            <iyy>0.108855</iyy>
            <iyz>0.00707701</iyz>
            <izz>0.0418711</izz>
          </inertia>
        </inertial>
        <collision name='MP_ANKLE1_L_collision'>
          <pose>0 0 0 0 -0 0</pose>
          <geometry>
            <mesh>
              <scale>1 1 1</scale>
              <uri>/home/nao/ros_catkin_ecg_ws/src/darwin_description/meshes/ankle1_l_coll.stl</uri>
            </mesh>
          </geometry>
          <surface>
            <contact>
              <ode/>
            </contact>
            <friction>
              <ode/>
            </friction>
            <bounce/>
          </surface>
          <max_contacts>10</max_contacts>
        </collision>
        <visual name='MP_ANKLE1_L_visual'>
          <pose>0 0 0 0 -0 0</pose>
          <geometry>
            <mesh>
              <scale>1 1 1</scale>
              <uri>/home/nao/ros_catkin_ecg_ws/src/darwin_description/meshes/ankle1_l.STL</uri>
            </mesh>
          </geometry>
          <material>
            <script>
              <name>Gazebo/Grey</name>
              <uri>__default__</uri>
            </script>
          </material>
          <material>
            <script>
              <name>Gazebo/Grey</name>
              <uri>__default__</uri>
            </script>
          </material>
        </visual>
        <gravity>1</gravity>
        <velocity_decay>
          <linear>0</linear>
          <angular>0</angular>
        </velocity_decay>
        <self_collide>0</self_collide>
        <kinematic>0</kinematic>
      </link>
      <joint name='j_ankle1_l' type='revolute'>
        <child>MP_ANKLE1_L</child>
        <parent>MP_TIBIA_L</parent>
        <axis>
          <xyz>3e-06 1 -3e-06</xyz>
          <limit>
            <lower>-2.61799</lower>
            <upper>2.61799</upper>
            <effort>10</effort>
            <velocity>5.65487</velocity>
          </limit>
          <dynamics/>
        </axis>
      </joint>
      <link name='MP_ANKLE2_L'>
        <pose>-0.005 0.0369994 -0.308202 1.5608 -1.57079 1.58079</pose>
        <inertial>
          <pose>-0.025995 -0.009506 -0.000503 0 -0 0</pose>
          <mass>0.0794462</mass>
          <inertia>
            <ixx>0.120792</ixx>
            <ixy>-0.000797811</ixy>
            <ixz>-0.000393222</ixz>
            <iyy>0.108855</iyy>
            <iyz>0.00707701</iyz>
            <izz>0.0418711</izz>
          </inertia>
        </inertial>
        <collision name='MP_ANKLE2_L_collision'>
          <pose>0 0 0 0 -0 0</pose>
          <geometry>
            <mesh>
              <scale>1 1 1</scale>
              <uri>/home/nao/ros_catkin_ecg_ws/src/darwin_description/meshes/ankle2_l_coll.stl</uri>
            </mesh>
          </geometry>
          <max_contacts>1</max_contacts>
          <surface>
            <contact>
              <ode>
                <kp>1e+06</kp>
                <kd>10</kd>
                <min_depth>0.001</min_depth>
              </ode>
            </contact>
            <friction>
              <ode>
                <mu>9000</mu>
                <mu2>9000</mu2>
              </ode>
            </friction>
            <bounce/>
          </surface>
        </collision>
        <visual name='MP_ANKLE2_L_visual'>
          <pose>0 0 0 0 -0 0</pose>
          <geometry>
            <mesh>
              <scale>1 1 1</scale>
              <uri>/home/nao/ros_catkin_ecg_ws/src/darwin_description/meshes/ankle2_l.STL</uri>
            </mesh>
          </geometry>
          <material>
            <script>
              <name>Gazebo/Grey</name>
              <uri>__default__</uri>
            </script>
          </material>
          <material>
            <script>
              <name>Gazebo/Grey</name>
              <uri>__default__</uri>
            </script>
          </material>
        </visual>
        <gravity>1</gravity>
        <velocity_decay>
          <linear>0</linear>
          <angular>0</angular>
        </velocity_decay>
        <self_collide>0</self_collide>
        <kinematic>0</kinematic>
      </link>
      <joint name='j_ankle2_l' type='revolute'>
        <child>MP_ANKLE2_L</child>
        <parent>MP_ANKLE1_L</parent>
        <axis>
          <xyz>1 -3e-06 0</xyz>
          <limit>
            <lower>-2.61799</lower>
            <upper>2.61799</upper>
            <effort>10</effort>
            <velocity>5.65487</velocity>
          </limit>
          <dynamics/>
        </axis>
      </joint>
      <link name='MP_PELVIS_R'>
        <pose>-0.005 -0.037 -0.09355 3.14159 2.65359e-06 -1.5708</pose>
        <inertial>
          <pose>0 0.00048 0.018437 0 -0 0</pose>
          <mass>0.197</mass>
          <inertia>
            <ixx>0.122597</ixx>
            <ixy>0.000711275</ixy>
            <ixz>0.000811439</ixz>
            <iyy>0.110666</iyy>
            <iyz>-0.00716355</iyz>
            <izz>0.0418777</izz>
          </inertia>
        </inertial>
        <collision name='MP_PELVIS_R_collision'>
          <pose>0 0 0 0 -0 0</pose>
          <geometry>
            <mesh>
              <scale>1 1 1</scale>
              <uri>/home/nao/ros_catkin_ecg_ws/src/darwin_description/meshes/pelvis_r_coll.stl</uri>
            </mesh>
          </geometry>
          <surface>
            <contact>
              <ode/>
            </contact>
            <friction>
              <ode/>
            </friction>
            <bounce/>
          </surface>
          <max_contacts>10</max_contacts>
        </collision>
        <visual name='MP_PELVIS_R_visual'>
          <pose>0 0 0 0 -0 0</pose>
          <geometry>
            <mesh>
              <scale>1 1 1</scale>
              <uri>/home/nao/ros_catkin_ecg_ws/src/darwin_description/meshes/pelvis_r.STL</uri>
            </mesh>
          </geometry>
          <material>
            <script>
              <name>Gazebo/Grey</name>
              <uri>__default__</uri>
            </script>
          </material>
          <material>
            <script>
              <name>Gazebo/Grey</name>
              <uri>__default__</uri>
            </script>
          </material>
        </visual>
        <gravity>1</gravity>
        <velocity_decay>
          <linear>0</linear>
          <angular>0</angular>
        </velocity_decay>
        <self_collide>0</self_collide>
        <kinematic>0</kinematic>
      </link>
      <joint name='j_pelvis_r' type='revolute'>
        <child>MP_PELVIS_R</child>
        <parent>base_link</parent>
        <axis>
          <xyz>0 3e-06 -1</xyz>
          <limit>
            <lower>-2.61799</lower>
            <upper>2.61799</upper>
            <effort>10</effort>
            <velocity>5.65487</velocity>
          </limit>
          <dynamics/>
        </axis>
      </joint>
      <link name='MP_THIGH1_R'>
        <pose>-0.005 -0.0369999 -0.122202 1.5708 2.65359e-06 -1.5708</pose>
        <inertial>
          <pose>7.9e-05 -0.018242 0.0138735 0 -0 0</pose>
          <mass>0.119043</mass>
          <inertia>
            <ixx>0.0979503</ixx>
            <ixy>0.00121194</ixy>
            <ixz>-0.00021223</ixz>
            <iyy>0.0328483</iyy>
            <iyz>-0.0019474</iyz>
            <izz>0.114935</izz>
          </inertia>
        </inertial>
        <collision name='MP_THIGH1_R_collision'>
          <pose>0 0 0 0 -0 0</pose>
          <geometry>
            <mesh>
              <scale>1 1 1</scale>
              <uri>/home/nao/ros_catkin_ecg_ws/src/darwin_description/meshes/thigh1_r_coll.stl</uri>
            </mesh>
          </geometry>
          <surface>
            <contact>
              <ode/>
            </contact>
            <friction>
              <ode/>
            </friction>
            <bounce/>
          </surface>
          <max_contacts>10</max_contacts>
        </collision>
        <visual name='MP_THIGH1_R_visual'>
          <pose>0 0 0 0 -0 0</pose>
          <geometry>
            <mesh>
              <scale>1 1 1</scale>
              <uri>/home/nao/ros_catkin_ecg_ws/src/darwin_description/meshes/thigh1_r.STL</uri>
            </mesh>
          </geometry>
          <material>
            <script>
              <name>Gazebo/Grey</name>
              <uri>__default__</uri>
            </script>
          </material>
          <material>
            <script>
              <name>Gazebo/Grey</name>
              <uri>__default__</uri>
            </script>
          </material>
        </visual>
        <gravity>1</gravity>
        <velocity_decay>
          <linear>0</linear>
          <angular>0</angular>
        </velocity_decay>
        <self_collide>0</self_collide>
        <kinematic>0</kinematic>
      </link>
      <joint name='j_thigh1_r' type='revolute'>
        <child>MP_THIGH1_R</child>
        <parent>MP_PELVIS_R</parent>
        <axis>
          <xyz>-1 0 0</xyz>
          <limit>
            <lower>-2.61799</lower>
            <upper>2.61799</upper>
            <effort>10</effort>
            <velocity>5.65487</velocity>
          </limit>
          <dynamics/>
        </axis>
      </joint>
      <link name='MP_THIGH2_R'>
        <pose>-0.005 -0.0369999 -0.122202 -0.0102003 1.57079 1.5606</pose>
        <inertial>
          <pose>0.062965 -0.000323 0.000692 0 -0 0</pose>
          <mass>0.119043</mass>
          <inertia>
            <ixx>0.0979503</ixx>
            <ixy>0.00121194</ixy>
            <ixz>-0.00021223</ixz>
            <iyy>0.0328483</iyy>
            <iyz>-0.0019474</iyz>
            <izz>0.114935</izz>
          </inertia>
        </inertial>
        <collision name='MP_THIGH2_R_collision'>
          <pose>0 0 0 0 -0 0</pose>
          <geometry>
            <mesh>
              <scale>1 1 1</scale>
              <uri>/home/nao/ros_catkin_ecg_ws/src/darwin_description/meshes/thigh2_r_coll.stl</uri>
            </mesh>
          </geometry>
          <surface>
            <contact>
              <ode/>
            </contact>
            <friction>
              <ode/>
            </friction>
            <bounce/>
          </surface>
          <max_contacts>10</max_contacts>
        </collision>
        <visual name='MP_THIGH2_R_visual'>
          <pose>0 0 0 0 -0 0</pose>
          <geometry>
            <mesh>
              <scale>1 1 1</scale>
              <uri>/home/nao/ros_catkin_ecg_ws/src/darwin_description/meshes/thigh2_r.STL</uri>
            </mesh>
          </geometry>
          <material>
            <script>
              <name>Gazebo/Grey</name>
              <uri>__default__</uri>
            </script>
          </material>
          <material>
            <script>
              <name>Gazebo/Grey</name>
              <uri>__default__</uri>
            </script>
          </material>
        </visual>
        <gravity>1</gravity>
        <velocity_decay>
          <linear>0</linear>
          <angular>0</angular>
        </velocity_decay>
        <self_collide>0</self_collide>
        <kinematic>0</kinematic>
      </link>
      <joint name='j_thigh2_r' type='revolute'>
        <child>MP_THIGH2_R</child>
        <parent>MP_THIGH1_R</parent>
        <axis>
          <xyz>0 1 3e-06</xyz>
          <limit>
            <lower>-2.61799</lower>
            <upper>2.61799</upper>
            <effort>10</effort>
            <velocity>5.65487</velocity>
          </limit>
          <dynamics/>
        </axis>
      </joint>
      <link name='MP_TIBIA_R'>
        <pose>-0.005 -0.0369997 -0.215202 -0.0102003 1.57079 1.5606</pose>
        <inertial>
          <pose>0.053955 0.006548 -0.000592 0 -0 0</pose>
          <mass>0.0703098</mass>
          <inertia>
            <ixx>0.0933696</ixx>
            <ixy>-0.000935674</ixy>
            <ixz>-0.000239921</ixz>
            <iyy>0.0462955</iyy>
            <iyz>-0.0128585</iyz>
            <izz>0.113515</izz>
          </inertia>
        </inertial>
        <collision name='MP_TIBIA_R_collision'>
          <pose>0 0 0 0 -0 0</pose>
          <geometry>
            <mesh>
              <scale>1 1 1</scale>
              <uri>/home/nao/ros_catkin_ecg_ws/src/darwin_description/meshes/tibia_r_coll.stl</uri>
            </mesh>
          </geometry>
          <surface>
            <contact>
              <ode/>
            </contact>
            <friction>
              <ode/>
            </friction>
            <bounce/>
          </surface>
          <max_contacts>10</max_contacts>
        </collision>
        <visual name='MP_TIBIA_R_visual'>
          <pose>0 0 0 0 -0 0</pose>
          <geometry>
            <mesh>
              <scale>1 1 1</scale>
              <uri>/home/nao/ros_catkin_ecg_ws/src/darwin_description/meshes/tibia_r.STL</uri>
            </mesh>
          </geometry>
          <material>
            <script>
              <name>Gazebo/Grey</name>
              <uri>__default__</uri>
            </script>
          </material>
          <material>
            <script>
              <name>Gazebo/Grey</name>
              <uri>__default__</uri>
            </script>
          </material>
        </visual>
        <gravity>1</gravity>
        <velocity_decay>
          <linear>0</linear>
          <angular>0</angular>
        </velocity_decay>
        <self_collide>0</self_collide>
        <kinematic>0</kinematic>
      </link>
      <joint name='j_tibia_r' type='revolute'>
        <child>MP_TIBIA_R</child>
        <parent>MP_THIGH2_R</parent>
        <axis>
          <xyz>0 1 3e-06</xyz>
          <limit>
            <lower>-2.61799</lower>
            <upper>2.61799</upper>
            <effort>10</effort>
            <velocity>5.65487</velocity>
          </limit>
          <dynamics/>
        </axis>
      </joint>
      <link name='MP_ANKLE1_R'>
        <pose>-0.005 -0.0369994 -0.308202 3.13139 1.57079 1.5606</pose>
        <inertial>
          <pose>-0.000214 -0.018536 -0.013873 0 -0 0</pose>
          <mass>0.167108</mass>
          <inertia>
            <ixx>0.120792</ixx>
            <ixy>-0.000797811</ixy>
            <ixz>-0.000393222</ixz>
            <iyy>0.108855</iyy>
            <iyz>0.00707701</iyz>
            <izz>0.0418711</izz>
          </inertia>
        </inertial>
        <collision name='MP_ANKLE1_R_collision'>
          <pose>0 0 0 0 -0 0</pose>
          <geometry>
            <mesh>
              <scale>1 1 1</scale>
              <uri>/home/nao/ros_catkin_ecg_ws/src/darwin_description/meshes/ankle1_r_coll.stl</uri>
            </mesh>
          </geometry>
          <surface>
            <contact>
              <ode/>
            </contact>
            <friction>
              <ode/>
            </friction>
            <bounce/>
          </surface>
          <max_contacts>10</max_contacts>
        </collision>
        <visual name='MP_ANKLE1_R_visual'>
          <pose>0 0 0 0 -0 0</pose>
          <geometry>
            <mesh>
              <scale>1 1 1</scale>
              <uri>/home/nao/ros_catkin_ecg_ws/src/darwin_description/meshes/ankle1_r.STL</uri>
            </mesh>
          </geometry>
          <material>
            <script>
              <name>Gazebo/Grey</name>
              <uri>__default__</uri>
            </script>
          </material>
          <material>
            <script>
              <name>Gazebo/Grey</name>
              <uri>__default__</uri>
            </script>
          </material>
        </visual>
        <gravity>1</gravity>
        <velocity_decay>
          <linear>0</linear>
          <angular>0</angular>
        </velocity_decay>
        <self_collide>0</self_collide>
        <kinematic>0</kinematic>
      </link>
      <joint name='j_ankle1_r' type='revolute'>
        <child>MP_ANKLE1_R</child>
        <parent>MP_TIBIA_R</parent>
        <axis>
          <xyz>3e-06 -1 -3e-06</xyz>
          <limit>
            <lower>-2.61799</lower>
            <upper>2.61799</upper>
            <effort>10</effort>
            <velocity>5.65487</velocity>
          </limit>
          <dynamics/>
        </axis>
      </joint>
      <link name='MP_ANKLE2_R'>
        <pose>-0.005 -0.0369994 -0.308202 1.56059 1.57079 1.5606</pose>
        <inertial>
          <pose>0.025995 -0.009506 -0.000503 0 -0 0</pose>
          <mass>0.0794462</mass>
          <inertia>
            <ixx>0.120792</ixx>
            <ixy>-0.000797811</ixy>
            <ixz>-0.000393222</ixz>
            <iyy>0.108855</iyy>
            <iyz>0.00707701</iyz>
            <izz>0.0418711</izz>
          </inertia>
        </inertial>
        <collision name='MP_ANKLE2_R_collision'>
          <pose>0 0 0 0 -0 0</pose>
          <geometry>
            <mesh>
              <scale>1 1 1</scale>
              <uri>/home/nao/ros_catkin_ecg_ws/src/darwin_description/meshes/ankle2_r_coll.stl</uri>
            </mesh>
          </geometry>
          <max_contacts>1</max_contacts>
          <surface>
            <contact>
              <ode>
                <kp>1e+06</kp>
                <kd>10</kd>
                <min_depth>0.001</min_depth>
              </ode>
            </contact>
            <friction>
              <ode>
                <mu>9000</mu>
                <mu2>9000</mu2>
              </ode>
            </friction>
            <bounce/>
          </surface>
        </collision>
        <visual name='MP_ANKLE2_R_visual'>
          <pose>0 0 0 0 -0 0</pose>
          <geometry>
            <mesh>
              <scale>1 1 1</scale>
              <uri>/home/nao/ros_catkin_ecg_ws/src/darwin_description/meshes/ankle2_r.STL</uri>
            </mesh>
          </geometry>
          <material>
            <script>
              <name>Gazebo/Grey</name>
              <uri>__default__</uri>
            </script>
          </material>
          <material>
            <script>
              <name>Gazebo/Grey</name>
              <uri>__default__</uri>
            </script>
          </material>
        </visual>
        <gravity>1</gravity>
        <velocity_decay>
          <linear>0</linear>
          <angular>0</angular>
        </velocity_decay>
        <self_collide>0</self_collide>
        <kinematic>0</kinematic>
      </link>
      <joint name='j_ankle2_r' type='revolute'>
        <child>MP_ANKLE2_R</child>
        <parent>MP_ANKLE1_R</parent>
        <axis>
          <xyz>1 3e-06 0</xyz>
          <limit>
            <lower>-2.61799</lower>
            <upper>2.61799</upper>
            <effort>10</effort>
            <velocity>5.65487</velocity>
          </limit>
          <dynamics/>
        </axis>
      </joint>
      <plugin name='gazebo_ros_control' filename='libgazebo_ros_control.so'>
        <robotNamespace>/darwin</robotNamespace>
      </plugin>
      <static>0</static>
      <plugin name='gazebo_ros_imu' filename='libhector_gazebo_ros_imu.so'>
        <updateRate>50</updateRate>
        <serviceName>/darwin/imu_service</serviceName>
        <topicName>/darwin/imu</topicName>
        <gaussianNoise>0</gaussianNoise>
        <robotNamespace>/</robotNamespace>
        <bodyName>base_link</bodyName>
        <xyzOffset>0 0 0</xyzOffset>
        <rpyOffset>0 0 -0.0122735</rpyOffset>
      </plugin>
      <pose>0 0 0.3417 0 -0 0</pose>
    </model>
    <state world_name='default'>
      <sim_time>167270 498000000</sim_time>
      <real_time>0 0</real_time>
      <wall_time>1455675457 812391570</wall_time>
      <model name='BuildingDefaultName'>
        <pose>0 0 0 0 -0 0</pose>
        <link name='__default__'>
          <pose>0 0 0 0 -0 0</pose>
          <velocity>0 0 0 0 -0 0</velocity>
          <acceleration>0 0 0 0 -0 0</acceleration>
          <wrench>0 0 0 0 -0 0</wrench>
        </link>
      </model>
      <model name='cafe_table'>
        <pose>-2.5513 5 -0.569512 0 -0 0</pose>
        <link name='link'>
          <pose>-2.5513 5 -0.569512 0 -0 0</pose>
          <velocity>0 0 0 0 -0 0</velocity>
          <acceleration>0 0 0 0 -0 0</acceleration>
          <wrench>0 0 0 0 -0 0</wrench>
        </link>
      </model>
      <model name='cafe_table_0'>
        <pose>4.51018 2.95276 -0.571728 0 -0 0.102062</pose>
        <link name='link'>
          <pose>4.51018 2.95276 -0.571728 0 -0 0.102062</pose>
          <velocity>0 0 0 0 -0 0</velocity>
          <acceleration>0 0 0 0 -0 0</acceleration>
          <wrench>0 0 0 0 -0 0</wrench>
        </link>
      </model>
      <model name='coke_can'>
        <pose>4.07614 2.94249 0.199383 -0.00708 -0.004015 0.018333</pose>
        <link name='link'>
          <pose>4.07614 2.94249 0.199383 -0.00708 -0.004015 0.018333</pose>
          <velocity>0 0 0 0 -0 0</velocity>
          <acceleration>0 0 0 0 -0 0</acceleration>
          <wrench>0 0 0 0 -0 0</wrench>
        </link>
      </model>
      <model name='darwin'>
        <pose>3.91113 2.91988 0.312994 0.001629 -0.00458 0.078161</pose>
        <link name='MP_ANKLE1_L'>
          <pose>3.90462 2.95699 0.004833 1.2303 -1.56594 -2.72294</pose>
          <velocity>0 0 0 0 -0 0</velocity>
          <acceleration>0 0 0 0 -0 0</acceleration>
          <wrench>0 0 0 0 -0 0</wrench>
        </link>
        <link name='MP_ANKLE1_R'>
          <pose>3.9104 2.88321 0.004712 1.91373 1.56593 0.421107</pose>
          <velocity>0 0 0 0 -0 0</velocity>
          <acceleration>0 0 0 0 -0 0</acceleration>
          <wrench>0 0 0 0 -0 0</wrench>
        </link>
        <link name='MP_ANKLE2_L'>
          <pose>3.90462 2.95699 0.004833 -0.340492 -1.56594 -2.72294</pose>
          <velocity>0 0 0 0 -0 0</velocity>
          <acceleration>0 0 0 0 -0 0</acceleration>
          <wrench>0 0 0 0 -0 0</wrench>
        </link>
        <link name='MP_ANKLE2_R'>
          <pose>3.9104 2.88321 0.004712 0.342932 1.56593 0.421107</pose>
          <velocity>0 0 0 0 -0 0</velocity>
          <acceleration>0 0 0 0 -0 0</acceleration>
          <wrench>0 0 0 0 -0 0</wrench>
        </link>
        <link name='MP_ARM_GRIPPER_FIX_L'>
          <pose>3.89636 3.10933 0.297304 1.56622 -0.001629 1.64896</pose>
          <velocity>0 0 0 0 -0 0</velocity>
          <acceleration>0 0 0 0 -0 0</acceleration>
          <wrench>0 0 0 0 -0 0</wrench>
        </link>
        <link name='MP_ARM_GRIPPER_FIX_R'>
          <pose>3.92604 2.73049 0.296685 1.57538 0.001629 -1.49263</pose>
          <velocity>0 0 0 0 -0 0</velocity>
          <acceleration>0 0 0 0 -0 0</acceleration>
          <wrench>0 0 0 0 -0 0</wrench>
        </link>
        <link name='MP_ARM_GRIPPER_MOV_L'>
          <pose>3.89257 3.15716 0.307382 1.5623 -1.00161 1.65611</pose>
          <velocity>0 0 0 0 -0 0</velocity>
          <acceleration>0 0 0 0 -0 0</acceleration>
          <wrench>0 0 0 0 -0 0</wrench>
        </link>
        <link name='MP_ARM_GRIPPER_MOV_R'>
          <pose>3.92974 2.68262 0.306606 1.57926 -0.998355 -1.49975</pose>
          <velocity>0 0 0 0 -0 0</velocity>
          <acceleration>0 0 0 0 -0 0</acceleration>
          <wrench>0 0 0 0 -0 0</wrench>
        </link>
        <link name='MP_ARM_HIGH_L'>
          <pose>3.9048 3.00166 0.297128 1.57538 0.001629 -1.49263</pose>
          <velocity>0 0 0 0 -0 0</velocity>
          <acceleration>0 0 0 0 -0 0</acceleration>
          <wrench>0 0 0 0 -0 0</wrench>
        </link>
        <link name='MP_ARM_HIGH_R'>
          <pose>3.9176 2.83816 0.296861 1.56622 -0.001629 1.64897</pose>
          <velocity>0 0 0 0 -0 0</velocity>
          <acceleration>0 0 0 0 -0 0</acceleration>
          <wrench>0 0 0 0 -0 0</wrench>
        </link>
        <link name='MP_ARM_LOW_L'>
          <pose>3.91606 3.06273 0.297299 -0.00458 -0.001629 1.64896</pose>
          <velocity>0 0 0 0 -0 0</velocity>
          <acceleration>0 0 0 0 -0 0</acceleration>
          <wrench>0 0 0 0 -0 0</wrench>
        </link>
        <link name='MP_ARM_LOW_R'>
          <pose>3.93824 2.7796 0.296836 0.00458 0.001629 -1.49263</pose>
          <velocity>0 0 0 0 -0 0</velocity>
          <acceleration>0 0 0 0 -0 0</acceleration>
          <wrench>0 0 0 0 -0 0</wrench>
        </link>
        <link name='MP_HEAD'>
          <pose>3.91091 2.91978 0.363643 -1.57243 0.00458 -3.06343</pose>
          <velocity>0 0 0 0 -0 0</velocity>
          <acceleration>0 0 0 0 -0 0</acceleration>
          <wrench>0 0 0 0 -0 0</wrench>
        </link>
        <link name='MP_NECK'>
          <pose>3.91103 2.91983 0.336494 -0.00458 -0.001629 1.64897</pose>
          <velocity>0 0 0 0 -0 0</velocity>
          <acceleration>0 0 0 0 -0 0</acceleration>
          <wrench>0 0 0 0 -0 0</wrench>
        </link>
        <link name='MP_PELVIS_L'>
          <pose>3.90367 2.95656 0.219482 3.13701 -0.001626 1.64897</pose>
          <velocity>0 0 0 0 -0 0</velocity>
          <acceleration>0 0 0 0 -0 0</acceleration>
          <wrench>0 0 0 0 -0 0</wrench>
        </link>
        <link name='MP_PELVIS_R'>
          <pose>3.90945 2.88279 0.219362 -3.13701 0.001632 -1.49263</pose>
          <velocity>0 0 0 0 -0 0</velocity>
          <acceleration>0 0 0 0 -0 0</acceleration>
          <wrench>0 0 0 0 -0 0</wrench>
        </link>
        <link name='MP_SHOULDER_L'>
          <pose>3.90642 2.98005 0.313092 1.23024 -1.56593 -2.72288</pose>
          <velocity>0 0 0 0 -0 0</velocity>
          <acceleration>0 0 0 0 -0 0</acceleration>
          <wrench>0 0 0 0 -0 0</wrench>
        </link>
        <link name='MP_SHOULDER_R'>
          <pose>3.91584 2.85971 0.312896 1.9137 1.56594 0.421062</pose>
          <velocity>0 0 0 0 -0 0</velocity>
          <acceleration>0 0 0 0 -0 0</acceleration>
          <wrench>0 0 0 0 -0 0</wrench>
        </link>
        <link name='MP_THIGH1_L'>
          <pose>3.9038 2.95662 0.190831 -1.57538 -0.001626 1.64897</pose>
          <velocity>0 0 0 0 -0 0</velocity>
          <acceleration>0 0 0 0 -0 0</acceleration>
          <wrench>0 0 0 0 -0 0</wrench>
        </link>
        <link name='MP_THIGH1_R'>
          <pose>3.90958 2.88285 0.19071 1.57538 0.001632 -1.49263</pose>
          <velocity>0 0 0 0 -0 0</velocity>
          <acceleration>0 0 0 0 -0 0</acceleration>
          <wrench>0 0 0 0 -0 0</wrench>
        </link>
        <link name='MP_THIGH2_L'>
          <pose>3.9038 2.95662 0.190831 -1.91129 -1.56594 -2.72294</pose>
          <velocity>0 0 0 0 -0 0</velocity>
          <acceleration>0 0 0 0 -0 0</acceleration>
          <wrench>0 0 0 0 -0 0</wrench>
        </link>
        <link name='MP_THIGH2_R'>
          <pose>3.90958 2.88285 0.19071 -1.22786 1.56593 0.421107</pose>
          <velocity>0 0 0 0 -0 0</velocity>
          <acceleration>0 0 0 0 -0 0</acceleration>
          <wrench>0 0 0 0 -0 0</wrench>
        </link>
        <link name='MP_TIBIA_L'>
          <pose>3.90421 2.9568 0.097832 -1.91129 -1.56594 -2.72294</pose>
          <velocity>0 0 0 0 -0 0</velocity>
          <acceleration>0 0 0 0 -0 0</acceleration>
          <wrench>0 0 0 0 -0 0</wrench>
        </link>
        <link name='MP_TIBIA_R'>
          <pose>3.90999 2.88303 0.097711 -1.22786 1.56593 0.421107</pose>
          <velocity>0 0 0 0 -0 0</velocity>
          <acceleration>0 0 0 0 -0 0</acceleration>
          <wrench>0 0 0 0 -0 0</wrench>
        </link>
        <link name='base_link'>
          <pose>3.91113 2.91988 0.312994 0.001629 -0.00458 0.078161</pose>
          <velocity>0 0 0 0 -0 0</velocity>
          <acceleration>0 0 0 0 -0 0</acceleration>
          <wrench>0 0 0 0 -0 0</wrench>
        </link>
      </model>
      <model name='ground_plane'>
        <pose>0 0 0 0 -0 0</pose>
        <link name='link'>
          <pose>0 0 0 0 -0 0</pose>
          <velocity>0 0 0 0 -0 0</velocity>
          <acceleration>0 0 0 0 -0 0</acceleration>
          <wrench>0 0 0 0 -0 0</wrench>
        </link>
      </model>
    </state>
    <gui fullscreen='0'>
      <camera name='user_camera'>
        <pose>3.71796 2.65461 1.73779 7.71457e-19 1.42979 0.001812</pose>
        <view_controller>orbit</view_controller>
      </camera>
    </gui>
    <model name='BuildingDefaultName'>
      <static>1</static>
      <link name='__default__'>
        <velocity_decay>
          <linear>0</linear>
          <angular>0</angular>
        </velocity_decay>
        <self_collide>0</self_collide>
        <kinematic>0</kinematic>
        <gravity>1</gravity>
      </link>
    </model>
    <model name='coke_can'>
      <link name='link'>
        <inertial>
          <pose>-0.01 -0.012 0.15 0 -0 0</pose>
          <mass>0.39</mass>
          <inertia>
            <ixx>0.00058</ixx>
            <ixy>0</ixy>
            <ixz>0</ixz>
            <iyy>0.00058</iyy>
            <iyz>0</iyz>
            <izz>0.00019</izz>
          </inertia>
        </inertial>
        <collision name='collision'>
          <pose>0 0 -0.46 0 -0 0</pose>
          <geometry>
            <mesh>
              <uri>model://coke_can/meshes/coke_can.dae</uri>
            </mesh>
          </geometry>
          <surface>
            <friction>
              <ode>
                <mu>1</mu>
                <mu2>1</mu2>
              </ode>
            </friction>
            <contact>
              <ode>
                <kp>1e+07</kp>
                <kd>1</kd>
                <min_depth>0.001</min_depth>
                <max_vel>0.1</max_vel>
              </ode>
            </contact>
            <bounce/>
          </surface>
          <max_contacts>10</max_contacts>
        </collision>
        <visual name='visual'>
          <pose>0 0 -0.46 0 -0 0</pose>
          <geometry>
            <mesh>
              <uri>model://coke_can/meshes/coke_can.dae</uri>
            </mesh>
          </geometry>
        </visual>
        <velocity_decay>
          <linear>0</linear>
          <angular>0</angular>
        </velocity_decay>
        <self_collide>0</self_collide>
        <kinematic>0</kinematic>
        <gravity>1</gravity>
      </link>
      <pose>3.58112 3 0 0 -0 0</pose>
      <static>0</static>
    </model>
    <model name='cafe_table'>
      <static>1</static>
      <link name='link'>
        <collision name='surface'>
          <pose>0 0 0.755 0 -0 0</pose>
          <geometry>
            <box>
              <size>0.913 0.913 0.04</size>
            </box>
          </geometry>
          <max_contacts>10</max_contacts>
          <surface>
            <bounce/>
            <friction>
              <ode/>
            </friction>
            <contact>
              <ode/>
            </contact>
          </surface>
        </collision>
        <collision name='column'>
          <pose>0 0 0.37 0 -0 0</pose>
          <geometry>
            <box>
              <size>0.042 0.042 0.74</size>
            </box>
          </geometry>
          <max_contacts>10</max_contacts>
          <surface>
            <bounce/>
            <friction>
              <ode/>
            </friction>
            <contact>
              <ode/>
            </contact>
          </surface>
        </collision>
        <collision name='base'>
          <pose>0 0 0.02 0 -0 0</pose>
          <geometry>
            <box>
              <size>0.56 0.56 0.04</size>
            </box>
          </geometry>
          <max_contacts>10</max_contacts>
          <surface>
            <bounce/>
            <friction>
              <ode/>
            </friction>
            <contact>
              <ode/>
            </contact>
          </surface>
        </collision>
        <visual name='visual'>
          <geometry>
            <mesh>
              <uri>model://cafe_table/meshes/cafe_table.dae</uri>
            </mesh>
          </geometry>
        </visual>
        <velocity_decay>
          <linear>0</linear>
          <angular>0</angular>
        </velocity_decay>
        <self_collide>0</self_collide>
        <kinematic>0</kinematic>
        <gravity>1</gravity>
      </link>
      <pose>-2.5513 5 0 0 -0 0</pose>
    </model>
    <model name='cafe_table_0'>
      <static>1</static>
      <link name='link'>
        <collision name='surface'>
          <pose>0 0 0.755 0 -0 0</pose>
          <geometry>
            <box>
              <size>0.913 0.913 0.04</size>
            </box>
          </geometry>
          <max_contacts>10</max_contacts>
          <surface>
            <bounce/>
            <friction>
              <ode/>
            </friction>
            <contact>
              <ode/>
            </contact>
          </surface>
        </collision>
        <collision name='column'>
          <pose>0 0 0.37 0 -0 0</pose>
          <geometry>
            <box>
              <size>0.042 0.042 0.74</size>
            </box>
          </geometry>
          <max_contacts>10</max_contacts>
          <surface>
            <bounce/>
            <friction>
              <ode/>
            </friction>
            <contact>
              <ode/>
            </contact>
          </surface>
        </collision>
        <collision name='base'>
          <pose>0 0 0.02 0 -0 0</pose>
          <geometry>
            <box>
              <size>0.56 0.56 0.04</size>
            </box>
          </geometry>
          <max_contacts>10</max_contacts>
          <surface>
            <bounce/>
            <friction>
              <ode/>
            </friction>
            <contact>
              <ode/>
            </contact>
          </surface>
        </collision>
        <visual name='visual'>
          <geometry>
            <mesh>
              <uri>model://cafe_table/meshes/cafe_table.dae</uri>
            </mesh>
          </geometry>
        </visual>
        <velocity_decay>
          <linear>0</linear>
          <angular>0</angular>
        </velocity_decay>
        <self_collide>0</self_collide>
        <kinematic>0</kinematic>
        <gravity>1</gravity>
      </link>
      <pose>4.43578 3 0 0 -0 0</pose>
    </model>
  </world>
</sdf>
